Workbook

Sheet Form Responses 1
A1: Timestamp | B1: Column 2 | C1: TANGGAL | D1: DESKRIPSI | E1: NOMINAL | F1: KATEGORI | G1: SUMBER/AKUN | H1: AKUN TUJUAN | I1: UPLOAD GAMBAR NOTA TRANSAKSI
A2: 46027.478 | C2: 46027 | D2: Gaji | E2: 2000000 | F2: PEMASUKAN | G2: SINARMAS
A3: 46027.489 | C3: 46027 | D3: Tarik tunai | E3: 1000000 | F3: MUTASI/TRANSFER | G3: SINARMAS | H3: CASH
A4: 46027.526 | C4: 46027 | D4: Kondangan/buwuh | E4: 50000 | F4: PENGELUARAN | G4: CASH
A5: 46028.109 | C5: 46028 | D5: Untuk langganan iclod | E5: 50000 | F5: MUTASI/TRANSFER | G5: SINARMAS | H5: DANA
A6: 46028.22 | C6: 46028 | D6: Bayar spay | E6: 500000 | F6: MUTASI/TRANSFER | G6: SINARMAS | H6: SHOPEE PAY
A7: 46028.222 | C7: 46027 | D7: Nabung | E7: 500000 | F7: PENGELUARAN | G7: CASH
A8: 46028.223 | C8: 46027 | D8: Memberi mama | E8: 300000 | F8: PENGELUARAN | G8: CASH
A9: 46028.246 | C9: 46027 | D9: Jajan | E9: 37000 | F9: PENGELUARAN | G9: CASH
A10: 46028.246 | C10: 46027 | D10: Memberi adek | E10: 50000 | F10: PENGELUARAN | G10: CASH
A11: 46028.262 | C11: 46028 | D11: Bayaran hutang cak pendik | E11: 50000 | F11: PENGELUARAN | G11: SINARMAS | H11: SINARMAS
A12: 46028.484 | C12: 46028 | D12: Tagihan gmail Iphon | E12: 48000 | F12: PENGELUARAN | G12: DANA
A13: 46028.769 | C13: 46028 | D13: Bayar payleter | E13: 129806 | F13: PENGELUARAN | G13: SHOPEE PAY
A14: 46028.782 | C14: 46028 | D14: Jajan | E14: 15000 | F14: PENGELUARAN | G14: CASH
A15: 46030.25 | C15: 46029 | D15: Oper uang untuk bayar jajan (diva) | E15: 10000 | F15: PEMASUKAN | G15: SINARMAS
A16: 46030.25 | C16: 46029 | D16: Oper uang untuk bayar jajan (rozaq) | E16: 10000 | F16: PEMASUKAN | G16: SINARMAS
A17: 46030.251 | C17: 46030 | D17: Oper uang untuk bayar jajan (pak ray) | E17: 10000 | F17: PEMASUKAN | G17: SINARMAS
A18: 46030.251 | C18: 46029 | D18: Oper uang untuk bayar jajan (diva & rozaq) | E18: 20000 | F18: PENGELUARAN | G18: CASH
A19: 46030.251 | C19: 46030 | D19: Oper uang untuk bayar jajan (pak ray) | E19: 10000 | F19: PENGELUARAN | G19: CASH
A20: 46030.449 | C20: 46030 | D20: bayar cetak stiker | E20: 11000 | F20: PENGELUARAN | G20: SINARMAS
A21: 46030.524 | C21: 46030 | D21: Jajan | E21: 16200 | F21: PENGELUARAN | G21: SHOPEE PAY
A22: 46031.424 | C22: 46031 | D22: Bayar Spaylater | E22: 76066 | F22: PENGELUARAN | G22: SHOPEE PAY
A23: 46031.425 | C23: 46031 | D23: Bayar spinjam | E23: 100262 | F23: PENGELUARAN | G23: SHOPEE PAY
... A31: 46032.652 | C31: 46032 | D31: Bayar spayleter ricat | E31: 179731 | F31: PENGELUARAN | G31: SHOPEE PAY
A32: 46032.653 | C32: 46032 | D32: Bayar spayleter | E32: 50000 | F32: MUTASI/TRANSFER | G32: SINARMAS | H32: SHOPEE PAY
A33: 46032.657 | C33: 46032 | D33: Bayar spayleter | E33: 250491 | F33: PENGELUARAN | G33: SHOPEE PAY
A34: 46032.828 | C34: 46031 | D34: Memasukkan cempolong | E34: 10000 | F34: PENGELUARAN | G34: SINARMAS | I34: https://drive.google.com/open?id=134LqCvl_1Svd1sTJAzpoSjmL3_HCYA93
A35: 46033.401 | C35: 46033 | D35: Pertamax | E35: 30000 | F35: PENGELUARAN | G35: CASH
A36: 46033.415 | C36: 46033 | D36: Paket internet mama | E36: 28000 | F36: PENGELUARAN | G36: CASH
A37: 46033.677 | C37: 46033 | D37: TEST INPUT DATA | E37: 0 | F37: PENGELUARAN | G37: CASH | H37: -

Sheet dashboard
A2: PEMASUKAN | B2: PENGELUARAN | C2: MUTASI/TRANSFER
A3: =SUMIF(Form_Responses[KATEGORI],"PEMASUKAN",Form_Responses[NOMINAL]) -> 2738000 | B3: =SUMIF(Form_Responses[KATEGORI],"PENGELUARAN",Form_Responses[NOMINAL]) -> 2471617 | C3: =SUMIF(Form_Responses[KATEGORI],"MUTASI/TRANSFER",Form_Responses[NOMINAL]) -> 1600000
A7: NAMA SUMBER | B7: SALDO AWAL | C7: SISA SALDO
A8: CASH | B8: 0 | C8: =B8 + SUMIFS('Form Responses 1'!$E:$E,'Form Responses 1'!$F:$F, "PEMASUKAN", 'Form Responses 1'!G:G, $A8) + SUMIFS('Form Responses 1'!$E:$E,'Form Responses 1'!$F:$F, "MUTASI/TRANSFER", 'Form Responses 1'!H:H, $A8) - SUMIFS('Form Responses 1'!$E:$E,'Form Responses 1'!$F:$F, "PENGELUARAN", 'Form Responses 1'!G:G, $A8) - SUMIFS('Form Responses 1'!$E:$E,'Form Responses 1'!$F:$F, "MUTASI/TRANSFER", 'Form Responses 1'!G:G, $A8) -> 188000
A9: SINARMAS | B9: 0 | C9: =B9 + SUMIFS('Form Responses 1'!$E:$E,'Form Responses 1'!$F:$F, "PEMASUKAN", 'Form Responses 1'!G:G, $A9) + SUMIFS('Form Responses 1'!$E:$E,'Form Responses 1'!$F:$F, "MUTASI/TRANSFER", 'Form Responses 1'!H:H, $A9) - SUMIFS('Form Responses 1'!$E:$E,'Form Responses 1'!$F:$F, "PENGELUARAN", 'Form Responses 1'!G:G, $A9) - SUMIFS('Form Responses 1'!$E:$E,'Form Responses 1'!$F:$F, "MUTASI/TRANSFER", 'Form Responses 1'!G:G, $A9) -> 122000
A10: DANA | B10: 2630 | C10: =B10 + SUMIFS('Form Responses 1'!$E:$E,'Form Responses 1'!$F:$F, "PEMASUKAN", 'Form Responses 1'!G:G, $A10) + SUMIFS('Form Responses 1'!$E:$E,'Form Responses 1'!$F:$F, "MUTASI/TRANSFER", 'Form Responses 1'!H:H, $A10) - SUMIFS('Form Responses 1'!$E:$E,'Form Responses 1'!$F:$F, "PENGELUARAN", 'Form Responses 1'!G:G, $A10) - SUMIFS('Form Responses 1'!$E:$E,'Form Responses 1'!$F:$F, "MUTASI/TRANSFER", 'Form Responses 1'!G:G, $A10) -> 4630
A11: SEABANK | B11: 5418 | C11: =B11 + SUMIFS('Form Responses 1'!$E:$E,'Form Responses 1'!$F:$F, "PEMASUKAN", 'Form Responses 1'!G:G, $A11) + SUMIFS('Form Responses 1'!$E:$E,'Form Responses 1'!$F:$F, "MUTASI/TRANSFER", 'Form Responses 1'!H:H, $A11) - SUMIFS('Form Responses 1'!$E:$E,'Form Responses 1'!$F:$F, "PENGELUARAN", 'Form Responses 1'!G:G, $A11) - SUMIFS('Form Responses 1'!$E:$E,'Form Responses 1'!$F:$F, "MUTASI/TRANSFER", 'Form Responses 1'!G:G, $A11) -> 5418
A12: LIVIN MANDIRI | B12: 11400 | C12: =B12 + SUMIFS('Form Responses 1'!$E:$E,'Form Responses 1'!$F:$F, "PEMASUKAN", 'Form Responses 1'!G:G, $A12) + SUMIFS('Form Responses 1'!$E:$E,'Form Responses 1'!$F:$F, "MUTASI/TRANSFER", 'Form Responses 1'!H:H, $A12) - SUMIFS('Form Responses 1'!$E:$E,'Form Responses 1'!$F:$F, "PENGELUARAN", 'Form Responses 1'!G:G, $A12) - SUMIFS('Form Responses 1'!$E:$E,'Form Responses 1'!$F:$F, "MUTASI/TRANSFER", 'Form Responses 1'!G:G, $A12) -> 11400 | F12: =SUM(Table1[SISA SALDO]) -> 340962
A13: SHOPEE PAY | B13: 27975 | C13: =B13 + SUMIFS('Form Responses 1'!$E:$E,'Form Responses 1'!$F:$F, "PEMASUKAN", 'Form Responses 1'!G:G, $A13) + SUMIFS('Form Responses 1'!$E:$E,'Form Responses 1'!$F:$F, "MUTASI/TRANSFER", 'Form Responses 1'!H:H, $A13) - SUMIFS('Form Responses 1'!$E:$E,'Form Responses 1'!$F:$F, "PENGELUARAN", 'Form Responses 1'!G:G, $A13) - SUMIFS('Form Responses 1'!$E:$E,'Form Responses 1'!$F:$F, "MUTASI/TRANSFER", 'Form Responses 1'!G:G, $A13) -> -17642 | F13: 266383
A14: GOPAY | B14: 27156 | C14: =B14 + SUMIFS('Form Responses 1'!$E:$E,'Form Responses 1'!$F:$F, "PEMASUKAN", 'Form Responses 1'!G:G, $A14) + SUMIFS('Form Responses 1'!$E:$E,'Form Responses 1'!$F:$F, "MUTASI/TRANSFER", 'Form Responses 1'!H:H, $A14) - SUMIFS('Form Responses 1'!$E:$E,'Form Responses 1'!$F:$F, "PENGELUARAN", 'Form Responses 1'!G:G, $A14) - SUMIFS('Form Responses 1'!$E:$E,'Form Responses 1'!$F:$F, "MUTASI/TRANSFER", 'Form Responses 1'!G:G, $A14) -> 27156 | F14: =F12-F13 -> 74579
A18: NAMA SUMBER | B18: KETERANGAN | C18: NOMINAL
A19: =IFERROR(__xludf.DUMMYFUNCTION("QUERY('Form Responses 1'!A2:I1000, ""SELECT G, D, E WHERE G IS NOT NULL ORDER BY A DESC"", 0)"),"CASH") -> CASH | B19: =IFERROR(__xludf.DUMMYFUNCTION("""COMPUTED_VALUE"""),"TEST INPUT DATA") -> TEST INPUT DATA | C19: =IFERROR(__xludf.DUMMYFUNCTION("""COMPUTED_VALUE"""),0.0) -> 0
A20: =IFERROR(__xludf.DUMMYFUNCTION("""COMPUTED_VALUE"""),"CASH") -> CASH | B20: =IFERROR(__xludf.DUMMYFUNCTION("""COMPUTED_VALUE"""),"Paket internet mama") -> Paket internet mama | C20: =IFERROR(__xludf.DUMMYFUNCTION("""COMPUTED_VALUE"""),28000.0) -> 28000
A21: =IFERROR(__xludf.DUMMYFUNCTION("""COMPUTED_VALUE"""),"CASH") -> CASH | B21: =IFERROR(__xludf.DUMMYFUNCTION("""COMPUTED_VALUE"""),"Pertamax") -> Pertamax | C21: =IFERROR(__xludf.DUMMYFUNCTION("""COMPUTED_VALUE"""),30000.0) -> 30000
A22: =IFERROR(__xludf.DUMMYFUNCTION("""COMPUTED_VALUE"""),"SINARMAS") -> SINARMAS | B22: =IFERROR(__xludf.DUMMYFUNCTION("""COMPUTED_VALUE"""),"Memasukkan cempolong") -> Memasukkan cempolong | C22: =IFERROR(__xludf.DUMMYFUNCTION("""COMPUTED_VALUE"""),10000.0) -> 10000
A23: =IFERROR(__xludf.DUMMYFUNCTION("""COMPUTED_VALUE"""),"SHOPEE PAY") -> SHOPEE PAY | B23: =IFERROR(__xludf.DUMMYFUNCTION("""COMPUTED_VALUE"""),"Bayar spayleter") -> Bayar spayleter | C23: =IFERROR(__xludf.DUMMYFUNCTION("""COMPUTED_VALUE"""),250491.0) -> 250491
A24: =IFERROR(__xludf.DUMMYFUNCTION("""COMPUTED_VALUE"""),"SINARMAS") -> SINARMAS | B24: =IFERROR(__xludf.DUMMYFUNCTION("""COMPUTED_VALUE"""),"Bayar spayleter") -> Bayar spayleter | C24: =IFERROR(__xludf.DUMMYFUNCTION("""COMPUTED_VALUE"""),50000.0) -> 50000
A25: =IFERROR(__xludf.DUMMYFUNCTION("""COMPUTED_VALUE"""),"SHOPEE PAY") -> SHOPEE PAY | B25: =IFERROR(__xludf.DUMMYFUNCTION("""COMPUTED_VALUE"""),"Bayar spayleter ricat") -> Bayar spayleter ricat | C25: =IFERROR(__xludf.DUMMYFUNCTION("""COMPUTED_VALUE"""),179731.0) -> 179731
A26: =IFERROR(__xludf.DUMMYFUNCTION("""COMPUTED_VALUE"""),"SHOPEE PAY") -> SHOPEE PAY | B26: =IFERROR(__xludf.DUMMYFUNCTION("""COMPUTED_VALUE"""),"Bayar spylater (kombinasi aku dan ricat) ") -> Bayar spylater (kombinasi aku dan ricat) | C26: =IFERROR(__xludf.DUMMYFUNCTION("""COMPUTED_VALUE"""),260401.0) -> 260401
A27: =IFERROR(__xludf.DUMMYFUNCTION("""COMPUTED_VALUE"""),"SHOPEE PAY") -> SHOPEE PAY | B27: =IFERROR(__xludf.DUMMYFUNCTION("""COMPUTED_VALUE"""),"Bayar spaylater dari ricat") -> Bayar spaylater dari ricat | C27: =IFERROR(__xludf.DUMMYFUNCTION("""COMPUTED_VALUE"""),480000.0) -> 480000
A28: =IFERROR(__xludf.DUMMYFUNCTION("""COMPUTED_VALUE"""),"CASH") -> CASH | B28: =IFERROR(__xludf.DUMMYFUNCTION("""COMPUTED_VALUE"""),"Uang bayar wifi cash") -> Uang bayar wifi cash | C28: =IFERROR(__xludf.DUMMYFUNCTION("""COMPUTED_VALUE"""),167000.0) -> 167000
A29: =IFERROR(__xludf.DUMMYFUNCTION("""COMPUTED_VALUE"""),"SINARMAS") -> SINARMAS | B29: =IFERROR(__xludf.DUMMYFUNCTION("""COMPUTED_VALUE"""),"Bayar wifi") -> Bayar wifi | C29: =IFERROR(__xludf.DUMMYFUNCTION("""COMPUTED_VALUE"""),167000.0) -> 167000
A30: =IFERROR(__xludf.DUMMYFUNCTION("""COMPUTED_VALUE"""),"CASH") -> CASH | B30: =IFERROR(__xludf.DUMMYFUNCTION("""COMPUTED_VALUE"""),"Ganti uang print benner") -> Ganti uang print benner | C30: =IFERROR(__xludf.DUMMYFUNCTION("""COMPUTED_VALUE"""),61000.0) -> 61000
A31: =IFERROR(__xludf.DUMMYFUNCTION("""COMPUTED_VALUE"""),"SINARMAS") -> SINARMAS | B31: =IFERROR(__xludf.DUMMYFUNCTION("""COMPUTED_VALUE"""),"Bayar bener dan stiker k3") -> Bayar bener dan stiker k3 | C31: =IFERROR(__xludf.DUMMYFUNCTION("""COMPUTED_VALUE"""),70000.0) -> 70000
A32: =IFERROR(__xludf.DUMMYFUNCTION("""COMPUTED_VALUE"""),"SHOPEE PAY") -> SHOPEE PAY | B32: =IFERROR(__xludf.DUMMYFUNCTION("""COMPUTED_VALUE"""),"Bayar spinjam") -> Bayar spinjam | C32: =IFERROR(__xludf.DUMMYFUNCTION("""COMPUTED_VALUE"""),62660.0) -> 62660
A33: =IFERROR(__xludf.DUMMYFUNCTION("""COMPUTED_VALUE"""),"SHOPEE PAY") -> SHOPEE PAY | B33: =IFERROR(__xludf.DUMMYFUNCTION("""COMPUTED_VALUE"""),"Bayar spinjam") -> Bayar spinjam | C33: =IFERROR(__xludf.DUMMYFUNCTION("""COMPUTED_VALUE"""),100262.0) -> 100262
A34: =IFERROR(__xludf.DUMMYFUNCTION("""COMPUTED_VALUE"""),"SHOPEE PAY") -> SHOPEE PAY | B34: =IFERROR(__xludf.DUMMYFUNCTION("""COMPUTED_VALUE"""),"Bayar Spaylater") -> Bayar Spaylater | C34: =IFERROR(__xludf.DUMMYFUNCTION("""COMPUTED_VALUE"""),76066.0) -> 76066
A35: =IFERROR(__xludf.DUMMYFUNCTION("""COMPUTED_VALUE"""),"SHOPEE PAY") -> SHOPEE PAY | B35: =IFERROR(__xludf.DUMMYFUNCTION("""COMPUTED_VALUE"""),"Jajan") -> Jajan | C35: =IFERROR(__xludf.DUMMYFUNCTION("""COMPUTED_VALUE"""),16200.0) -> 16200
A36: =IFERROR(__xludf.DUMMYFUNCTION("""COMPUTED_VALUE"""),"SINARMAS") -> SINARMAS | B36: =IFERROR(__xludf.DUMMYFUNCTION("""COMPUTED_VALUE"""),"bayar cetak stiker") -> bayar cetak stiker | C36: =IFERROR(__xludf.DUMMYFUNCTION("""COMPUTED_VALUE"""),11000.0) -> 11000
A37: =IFERROR(__xludf.DUMMYFUNCTION("""COMPUTED_VALUE"""),"CASH") -> CASH | B37: =IFERROR(__xludf.DUMMYFUNCTION("""COMPUTED_VALUE"""),"Oper uang untuk bayar jajan (pak ray) ") -> Oper uang untuk bayar jajan (pak ray) | C37: =IFERROR(__xludf.DUMMYFUNCTION("""COMPUTED_VALUE"""),10000.0) -> 10000
A38: =IFERROR(__xludf.DUMMYFUNCTION("""COMPUTED_VALUE"""),"CASH") -> CASH | B38: =IFERROR(__xludf.DUMMYFUNCTION("""COMPUTED_VALUE"""),"Oper uang untuk bayar jajan (diva & rozaq) ") -> Oper uang untuk bayar jajan (diva & rozaq) | C38: =IFERROR(__xludf.DUMMYFUNCTION("""COMPUTED_VALUE"""),20000.0) -> 20000
A39: =IFERROR(__xludf.DUMMYFUNCTION("""COMPUTED_VALUE"""),"SINARMAS") -> SINARMAS | B39: =IFERROR(__xludf.DUMMYFUNCTION("""COMPUTED_VALUE"""),"Oper uang untuk bayar jajan (pak ray) ") -> Oper uang untuk bayar jajan (pak ray) | C39: =IFERROR(__xludf.DUMMYFUNCTION("""COMPUTED_VALUE"""),10000.0) -> 10000
A40: =IFERROR(__xludf.DUMMYFUNCTION("""COMPUTED_VALUE"""),"SINARMAS") -> SINARMAS | B40: =IFERROR(__xludf.DUMMYFUNCTION("""COMPUTED_VALUE"""),"Oper uang untuk bayar jajan (rozaq) ") -> Oper uang untuk bayar jajan (rozaq) | C40: =IFERROR(__xludf.DUMMYFUNCTION("""COMPUTED_VALUE"""),10000.0) -> 10000
A41: =IFERROR(__xludf.DUMMYFUNCTION("""COMPUTED_VALUE"""),"SINARMAS") -> SINARMAS | B41: =IFERROR(__xludf.DUMMYFUNCTION("""COMPUTED_VALUE"""),"Oper uang untuk bayar jajan (diva) ") -> Oper uang untuk bayar jajan (diva) | C41: =IFERROR(__xludf.DUMMYFUNCTION("""COMPUTED_VALUE"""),10000.0) -> 10000
A42: =IFERROR(__xludf.DUMMYFUNCTION("""COMPUTED_VALUE"""),"CASH") -> CASH | B42: =IFERROR(__xludf.DUMMYFUNCTION("""COMPUTED_VALUE"""),"Jajan") -> Jajan | C42: =IFERROR(__xludf.DUMMYFUNCTION("""COMPUTED_VALUE"""),15000.0) -> 15000
A43: =IFERROR(__xludf.DUMMYFUNCTION("""COMPUTED_VALUE"""),"SHOPEE PAY") -> SHOPEE PAY | B43: =IFERROR(__xludf.DUMMYFUNCTION("""COMPUTED_VALUE"""),"Bayar payleter") -> Bayar payleter | C43: =IFERROR(__xludf.DUMMYFUNCTION("""COMPUTED_VALUE"""),129806.0) -> 129806
A44: =IFERROR(__xludf.DUMMYFUNCTION("""COMPUTED_VALUE"""),"DANA") -> DANA | B44: =IFERROR(__xludf.DUMMYFUNCTION("""COMPUTED_VALUE"""),"Tagihan gmail Iphon") -> Tagihan gmail Iphon | C44: =IFERROR(__xludf.DUMMYFUNCTION("""COMPUTED_VALUE"""),48000.0) -> 48000
A45: =IFERROR(__xludf.DUMMYFUNCTION("""COMPUTED_VALUE"""),"SINARMAS") -> SINARMAS | B45: =IFERROR(__xludf.DUMMYFUNCTION("""COMPUTED_VALUE"""),"Bayaran hutang cak pendik") -> Bayaran hutang cak pendik | C45: =IFERROR(__xludf.DUMMYFUNCTION("""COMPUTED_VALUE"""),50000.0) -> 50000
A46: =IFERROR(__xludf.DUMMYFUNCTION("""COMPUTED_VALUE"""),"CASH") -> CASH | B46: =IFERROR(__xludf.DUMMYFUNCTION("""COMPUTED_VALUE"""),"Memberi adek") -> Memberi adek | C46: =IFERROR(__xludf.DUMMYFUNCTION("""COMPUTED_VALUE"""),50000.0) -> 50000
A47: =IFERROR(__xludf.DUMMYFUNCTION("""COMPUTED_VALUE"""),"CASH") -> CASH | B47: =IFERROR(__xludf.DUMMYFUNCTION("""COMPUTED_VALUE"""),"Jajan") -> Jajan | C47: =IFERROR(__xludf.DUMMYFUNCTION("""COMPUTED_VALUE"""),37000.0) -> 37000
...

Sheet Sheet1
B2: PEMASUKAN | D2: PENGELUARAN | F2: SISA SALDO | I2: UANG CASH | K2: SALDO SINARMAS | M2: SALDO DANA | O2: SALDO SEABANK
B3: =SUMIF('Form Responses 1'!$F:$F,"PEMASUKAN",'Form Responses 1'!$E:$E) -> 2738000 | D3: =SUMIF('Form Responses 1'!$F:$F,"PENGELUARAN",'Form Responses 1'!$E:$E) -> 2471617 | F3: =$B$3-$D$3 -> 266383 | I3: 76000 | K3: 12971 | M3: 7130 | O3: 5408
I5: SALDO LIVIN MANDIRI | K5: SALDO SHOPEE PAY | M5: SALDO GOPAY
I6: 21400 | K6: 53502 | M6: 27156
